<mujoco model="NaoH25V50">
  <compiler angle="radian"/>
  
  <default>
    <geom contype="0" conaffinity="0"/>
  </default>

  <asset>
    <mesh name="HeadYaw_0.10" file="HeadYaw_0.10.stl" scale="0.1 0.1 0.1"/>
    <mesh name="HeadPitch_0.10" file="HeadPitch_0.10.stl" scale="0.1 0.1 0.1"/>
    <mesh name="LHipYawPitch_0.10" file="LHipYawPitch_0.10.stl" scale="0.1 0.1 0.1"/>
    <mesh name="LHipRoll_0.10" file="LHipRoll_0.10.stl" scale="0.1 0.1 0.1"/>
    <mesh name="LHipPitch_0.10" file="LHipPitch_0.10.stl" scale="0.1 0.1 0.1"/>
    <mesh name="LKneePitch_0.10" file="LKneePitch_0.10.stl" scale="0.1 0.1 0.1"/>
    <mesh name="LAnklePitch_0.10" file="LAnklePitch_0.10.stl" scale="0.1 0.1 0.1"/>
    <mesh name="LAnkleRoll_0.10" file="LAnkleRoll_0.10.stl" scale="0.1 0.1 0.1"/>
    <mesh name="RHipYawPitch_0.10" file="RHipYawPitch_0.10.stl" scale="0.1 0.1 0.1"/>
    <mesh name="RHipRoll_0.10" file="RHipRoll_0.10.stl" scale="0.1 0.1 0.1"/>
    <mesh name="RHipPitch_0.10" file="RHipPitch_0.10.stl" scale="0.1 0.1 0.1"/>
    <mesh name="RKneePitch_0.10" file="RKneePitch_0.10.stl" scale="0.1 0.1 0.1"/>
    <mesh name="RAnklePitch_0.10" file="RAnklePitch_0.10.stl" scale="0.1 0.1 0.1"/>
    <mesh name="RAnkleRoll_0.10" file="RAnkleRoll_0.10.stl" scale="0.1 0.1 0.1"/>
    <mesh name="Torso_0.10" file="Torso_0.10.stl" scale="0.1 0.1 0.1"/>
    <mesh name="LShoulderPitch_0.10" file="LShoulderPitch_0.10.stl" scale="0.1 0.1 0.1"/>
    <mesh name="LShoulderRoll_0.10" file="LShoulderRoll_0.10.stl" scale="0.1 0.1 0.1"/>
    <mesh name="LElbowRoll_0.10" file="LElbowRoll_0.10.stl" scale="0.1 0.1 0.1"/>
    <mesh name="LWristYaw_0.10" file="LWristYaw_0.10.stl" scale="0.1 0.1 0.1"/>
    <mesh name="RShoulderPitch_0.10" file="RShoulderPitch_0.10.stl" scale="0.1 0.1 0.1"/>
    <mesh name="RShoulderRoll_0.10" file="RShoulderRoll_0.10.stl" scale="0.1 0.1 0.1"/>
    <mesh name="RElbowRoll_0.10" file="RElbowRoll_0.10.stl" scale="0.1 0.1 0.1"/>
    <mesh name="RWristYaw_0.10" file="RWristYaw_0.10.stl" scale="0.1 0.1 0.1"/>
    <mesh name="RFinger13_0.10" file="RFinger13_0.10.stl" scale="0.1 0.1 0.1"/>
    <mesh name="RFinger12_0.10" file="RFinger12_0.10.stl" scale="0.1 0.1 0.1"/>
    <mesh name="LFinger21_0.10" file="LFinger21_0.10.stl" scale="0.1 0.1 0.1"/>
    <mesh name="LFinger13_0.10" file="LFinger13_0.10.stl" scale="0.1 0.1 0.1"/>
    <mesh name="LFinger11_0.10" file="LFinger11_0.10.stl" scale="0.1 0.1 0.1"/>
    <mesh name="RFinger22_0.10" file="RFinger22_0.10.stl" scale="0.1 0.1 0.1"/>
    <mesh name="LFinger22_0.10" file="LFinger22_0.10.stl" scale="0.1 0.1 0.1"/>
    <mesh name="RFinger21_0.10" file="RFinger21_0.10.stl" scale="0.1 0.1 0.1"/>
    <mesh name="LFinger12_0.10" file="LFinger12_0.10.stl" scale="0.1 0.1 0.1"/>
    <mesh name="RFinger23_0.10" file="RFinger23_0.10.stl" scale="0.1 0.1 0.1"/>
    <mesh name="RFinger11_0.10" file="RFinger11_0.10.stl" scale="0.1 0.1 0.1"/>
    <mesh name="LFinger23_0.10" file="LFinger23_0.10.stl" scale="0.1 0.1 0.1"/>
    <mesh name="LThumb1_0.10" file="LThumb1_0.10.stl" scale="0.1 0.1 0.1"/>
    <mesh name="RThumb1_0.10" file="RThumb1_0.10.stl" scale="0.1 0.1 0.1"/>
    <mesh name="RThumb2_0.10" file="RThumb2_0.10.stl" scale="0.1 0.1 0.1"/>
    <mesh name="LThumb2_0.10" file="LThumb2_0.10.stl" scale="0.1 0.1 0.1"/>
  </asset>

  <worldbody>
    <geom type="mesh" mesh="Torso_0.10"/>
    <body name="Neck" pos="0 0 0.1265">
      <inertial pos="-1e-05 0 -0.02742" quat="0.70765 -0.00173495 0.00151894 0.706559" mass="0.07842" diaginertia="1.70396e-05 1.60324e-05 5.53348e-06"/>
      <joint name="HeadYaw" pos="0 0 0" axis="0 0 1" range="-2.08567 2.08567" actuatorfrcrange="-1.547 1.547"/>
      <geom type="mesh" mesh="HeadYaw_0.10"/>
      <body name="Head">
        <inertial pos="-0.00112 0 0.05258" quat="0.463877 0.585354 -0.492966 0.446277" mass="0.60533" diaginertia="0.000990592 0.000957952 0.000811033"/>
        <joint name="HeadPitch" pos="0 0 0" axis="0 1 0" range="-0.671952 0.514872" actuatorfrcrange="-1.532 1.532"/>
        <geom type="mesh" mesh="HeadPitch_0.10"/>
      </body>
    </body>
    <body name="LPelvis" pos="0 0.05 -0.085">
      <inertial pos="-0.00781 -0.01114 0.02661" quat="0.232303 0.656505 0.182148 0.69416" mass="0.06981" diaginertia="5.16414e-05 4.58792e-05 2.32239e-05"/>
      <joint name="LHipYawPitch" pos="0 0 0" axis="0 0.707107 -0.707107" range="-1.14529 0.740718" actuatorfrcrange="-3.348 3.348"/>
      <geom type="mesh" mesh="LHipYawPitch_0.10"/>
      <body name="LHip">
        <inertial pos="-0.01549 0.00029 -0.00515" quat="0.453959 0.527953 0.574067 0.430853" mass="0.14053" diaginertia="6.08587e-05 5.59269e-05 2.22526e-05"/>
        <joint name="LHipRoll" pos="0 0 0" axis="1 0 0" range="-0.379435 0.79046" actuatorfrcrange="-3.348 3.348"/>
        <geom type="mesh" mesh="LHipRoll_0.10"/>
        <body name="LThigh">
          <inertial pos="0.00138 0.00221 -0.05373" quat="0.992078 -0.0228023 -0.123519 -0.00190301" mass="0.38968" diaginertia="0.000524114 0.000465732 0.000286453"/>
          <joint name="LHipPitch" pos="0 0 0" axis="0 1 0" range="-1.53589 0.48398" actuatorfrcrange="-3.023 3.023"/>
          <geom type="mesh" mesh="LHipPitch_0.10"/>
          <body name="LTibia" pos="0 0 -0.1">
            <inertial pos="0.00453 0.00225 -0.04936" quat="0.997907 0.0169027 0.0579417 0.0232071" mass="0.30142" diaginertia="0.000449928 0.000388139 0.000181704"/>
            <joint name="LKneePitch" pos="0 0 0" axis="0 1 0" range="-0.0923279 2.11255" actuatorfrcrange="-3.023 3.023"/>
            <geom type="mesh" mesh="LKneePitch_0.10"/>
            <body name="LAnklePitch" pos="0 0 -0.1029">
              <inertial pos="0.00045 0.00029 0.00685" quat="0.447256 0.548803 0.537287 0.458368" mass="0.13416" diaginertia="6.79494e-05 5.56016e-05 3.14223e-05"/>
              <joint name="LAnklePitch" pos="0 0 0" axis="0 1 0" range="-1.18944 0.922581" actuatorfrcrange="-3.023 3.023"/>
              <geom type="mesh" mesh="LAnklePitch_0.10"/>
              <body name="l_ankle">
                <inertial pos="0.0254198 0.00330005 -0.0323906" quat="0.0134363 0.704739 -0.00974782 0.709273" mass="0.171848" diaginertia="0.000412891 0.000353334 8.70025e-05"/>
                <joint name="LAnkleRoll" pos="0 0 0" axis="1 0 0" range="-0.397761 0.768992" actuatorfrcrange="-3.348 3.348"/>
                <geom type="mesh" mesh="LAnkleRoll_0.10"/>
                <geom size="0.005 0.005 0.0025" pos="0.07025 -0.0231 -0.04511" type="box"/>
                <geom size="0.005 0.005 0.0025" pos="-0.02965 -0.0191 -0.04511" type="box"/>
                <geom size="0.005 0.005 0.0025" pos="0.07025 0.0299 -0.04511" type="box"/>
                <geom size="0.005 0.005 0.0025" pos="-0.03025 0.0299 -0.04511" type="box"/>
              </body>
            </body>
          </body>
        </body>
      </body>
    </body>
    <body name="RPelvis" pos="0 -0.05 -0.085">
      <inertial pos="-0.00781 0.01114 0.02661" quat="-0.286295 0.637526 -0.200888 0.686469" mass="0.06981" diaginertia="6.0003e-05 4.60859e-05 3.15895e-05"/>
      <joint name="RHipYawPitch" pos="0 0 0" axis="0 0.707107 0.707107" range="-1.14529 0.740718" actuatorfrcrange="-3.348 3.348"/>
      <geom type="mesh" mesh="RHipYawPitch_0.10"/>
      <body name="RHip">
        <inertial pos="-0.01549 -0.00029 -0.00515" quat="0.431269 0.573083 0.528698 0.453941" mass="0.14053" diaginertia="6.08554e-05 5.59208e-05 2.2268e-05"/>
        <joint name="RHipRoll" pos="0 0 0" axis="1 0 0" range="-0.79046 0.379435" actuatorfrcrange="-3.348 3.348"/>
        <geom type="mesh" mesh="RHipRoll_0.10"/>
        <body name="RThigh">
          <inertial pos="0.00138 -0.00221 -0.05373" quat="0.99203 0.0205489 -0.124311 0.000726212" mass="0.38968" diaginertia="0.000525121 0.000466802 0.000286518"/>
          <joint name="RHipPitch" pos="0 0 0" axis="0 1 0" range="-1.53589 0.48398" actuatorfrcrange="-3.0226 3.0226"/>
          <geom type="mesh" mesh="RHipPitch_0.10"/>
          <body name="RTibia" pos="0 0 -0.1">
            <inertial pos="0.00453 -0.00225 -0.04936" quat="0.99698 -0.0149083 0.0724691 -0.0235809" mass="0.30142" diaginertia="0.000452851 0.000387699 0.000177824"/>
            <joint name="RKneePitch" pos="0 0 0" axis="0 1 0" range="-0.0923279 2.11255" actuatorfrcrange="-3.0226 3.0226"/>
            <geom type="mesh" mesh="RKneePitch_0.10"/>
            <body name="RAnklePitch" pos="0 0 -0.1029">
              <inertial pos="0.00045 -0.00029 0.00685" quat="0.458219 0.537985 0.54818 0.447332" mass="0.13416" diaginertia="6.79942e-05 5.56532e-05 3.14175e-05"/>
              <joint name="RAnklePitch" pos="0 0 0" axis="0 1 0" range="-1.1863 0.932006" actuatorfrcrange="-3.0226 3.0226"/>
              <geom type="mesh" mesh="RAnklePitch_0.10"/>
              <body name="r_ankle">
                <inertial pos="0.0254198 -0.00330005 -0.0323906" quat="-0.0138336 0.704473 0.00894574 0.70954" mass="0.171848" diaginertia="0.000412175 0.000352454 8.68701e-05"/>
                <joint name="RAnkleRoll" pos="0 0 0" axis="1 0 0" range="-0.768992 0.397761" actuatorfrcrange="-3.348 3.348"/>
                <geom type="mesh" mesh="RAnkleRoll_0.10"/>
                <geom size="0.005 0.005 0.0025" pos="-0.03025 0.0191 -0.04511" type="box"/>
                <geom size="0.005 0.005 0.0025" pos="-0.02965 -0.0299 -0.04511" type="box"/>
                <geom size="0.005 0.005 0.0025" pos="0.07025 -0.0299 -0.04511" type="box"/>
                <geom size="0.005 0.005 0.0025" pos="0.07025 0.0231 -0.04511" type="box"/>
              </body>
            </body>
          </body>
        </body>
      </body>
    </body>
    <body name="LShoulder" pos="0 0.098 0.1">
      <inertial pos="-0.00165 -0.02663 0.00014" quat="0.353499 0.572853 -0.442525 0.592494" mass="0.09304" diaginertia="2.02186e-05 1.91002e-05 1.30704e-05"/>
      <joint name="LShoulderPitch" pos="0 0 0" axis="0 1 0" range="-2.08567 2.08567" actuatorfrcrange="-1.329 1.329"/>
      <geom type="mesh" mesh="LShoulderPitch_0.10"/>
      <body name="LBicep">
        <inertial pos="0.02455 0.00563 0.0033" quat="0.467645 0.46185 0.492756 0.570257" mass="0.15777" diaginertia="0.00027823 0.000242894 8.25818e-05"/>
        <joint name="LShoulderRoll" pos="0 0 0" axis="0 0 1" range="-0.314159 1.32645" actuatorfrcrange="-1.7835 1.7835"/>
        <geom type="mesh" mesh="LShoulderRoll_0.10"/>
        <body name="LElbow" pos="0.105 0.015 0">
          <inertial pos="-0.02744 0 -0.00014" quat="-0.000545392 0.711779 -0.000696018 0.702403" mass="0.06483" diaginertia="2.76333e-05 2.66179e-05 5.592e-06"/>
          <joint name="LElbowYaw" pos="0 0 0" axis="1 0 0" range="-2.08567 2.08567" actuatorfrcrange="-1.547 1.547"/>
          <body name="LForeArm">
            <inertial pos="0.02556 0.00281 0.00076" quat="0.481839 0.619088 0.422287 0.454131" mass="0.07761" diaginertia="3.9183e-05 3.6083e-05 2.37632e-05"/>
            <joint name="LElbowRoll" pos="0 0 0" axis="0 0 1" range="-1.54462 -0.0349066" actuatorfrcrange="-1.532 1.532"/>
            <geom type="mesh" mesh="LElbowRoll_0.10"/>
            <body name="l_wrist" pos="0.05595 0 0">
              <inertial pos="0.0343429 -0.000879924 0.00307817" quat="0.346669 0.607665 0.329523 0.634017" mass="0.185346" diaginertia="0.000137517 0.000131662 6.85403e-05"/>
              <joint name="LWristYaw" pos="0 0 0" axis="1 0 0" range="-1.82387 1.82387" actuatorfrcrange="-0.4075 0.4075"/>
              <geom type="mesh" mesh="LWristYaw_0.10"/>
              <geom pos="0.06907 -0.01157 -0.00304" quat="0.672286 0.564114 0.308141 -0.367227" type="mesh" mesh="LFinger21_0.10"/>
              <geom pos="0.07683 -0.0136681 -0.0149392" quat="0.413961 0.347354 0.540852 -0.644562" type="mesh" mesh="LFinger22_0.10"/>
              <geom pos="0.0708567 -0.0159358 -0.0277995" quat="0.0543039 0.0455657 0.64117 -0.764117" type="mesh" mesh="LFinger23_0.10"/>
              <geom pos="0.06907 0.01157 -0.00304" quat="0.564115 0.672285 0.367228 -0.30814" type="mesh" mesh="LFinger11_0.10"/>
              <geom pos="0.07683 0.0136681 -0.0149392" quat="0.347355 0.41396 0.644562 -0.540852" type="mesh" mesh="LFinger12_0.10"/>
              <geom pos="0.0708567 0.0159358 -0.0277995" quat="0.0455666 0.0543032 0.764117 -0.641171" type="mesh" mesh="LFinger13_0.10"/>
              <geom pos="0.04895 0 -0.02638" quat="0.706908 -0.70691 0.0167209 0.016721" type="mesh" mesh="LThumb1_0.10"/>
              <geom pos="0.0632939 -4.68797e-10 -0.027059" quat="0.628403 -0.628405 -0.324205 -0.324204" type="mesh" mesh="LThumb2_0.10"/>
              <body name="l_gripper" pos="0.05775 0 -0.01231">
                <inertial pos="0 0 0" mass="2e-06" diaginertia="1.1e-09 1.1e-09 1.1e-09"/>
                <joint name="LHand" pos="0 0 0" axis="1 0 0" range="0 1" actuatorfrcrange="-0.292 0.292"/>
              </body>
            </body>
          </body>
        </body>
      </body>
    </body>
    <body name="RShoulder" pos="0 -0.098 0.1">
      <inertial pos="-0.00165 0.02663 0.00014" quat="0.572853 0.353499 -0.592494 0.442525" mass="0.09304" diaginertia="2.02186e-05 1.91002e-05 1.30704e-05"/>
      <joint name="RShoulderPitch" pos="0 0 0" axis="0 1 0" range="-2.08567 2.08567" actuatorfrcrange="-1.329 1.329"/>
      <geom type="mesh" mesh="RShoulderPitch_0.10"/>
      <body name="RBicep">
        <inertial pos="0.02455 -0.00563 0.0033" quat="0.556969 0.570609 0.359404 0.484788" mass="0.15777" diaginertia="0.000287934 0.00025515 8.56154e-05"/>
        <joint name="RShoulderRoll" pos="0 0 0" axis="0 0 1" range="-1.32645 0.314159" actuatorfrcrange="-1.783 1.783"/>
        <geom type="mesh" mesh="RShoulderRoll_0.10"/>
        <body name="RElbow" pos="0.105 -0.015 0">
          <inertial pos="-0.02744 0 -0.00014" quat="-0.000545392 0.711779 -0.000696018 0.702403" mass="0.06483" diaginertia="2.76333e-05 2.66179e-05 5.592e-06"/>
          <joint name="RElbowYaw" pos="0 0 0" axis="1 0 0" range="-2.08567 2.08567" actuatorfrcrange="-1.547 1.547"/>
          <body name="RForeArm">
            <inertial pos="0.02556 -0.00281 0.00076" quat="0.453039 0.428011 0.593606 0.509111" mass="0.07761" diaginertia="3.92326e-05 3.59586e-05 2.39457e-05"/>
            <joint name="RElbowRoll" pos="0 0 0" axis="0 0 1" range="0.0349066 1.54462" actuatorfrcrange="-1.532 1.532"/>
            <geom type="mesh" mesh="RElbowRoll_0.10"/>
            <body name="r_wrist" pos="0.05595 0 0">
              <inertial pos="0.0343429 0.000879924 0.00307817" quat="0.42247 0.617994 0.303975 0.589239" mass="0.185346" diaginertia="0.000139344 0.00013174 6.66351e-05"/>
              <joint name="RWristYaw" pos="0 0 0" axis="1 0 0" range="-1.82387 1.82387" actuatorfrcrange="-0.4075 0.4075"/>
              <geom type="mesh" mesh="RWristYaw_0.10"/>
              <geom pos="0.06907 -0.01157 -0.00304" quat="0.672286 0.564114 0.308141 -0.367227" type="mesh" mesh="RFinger21_0.10"/>
              <geom pos="0.07683 -0.0136681 -0.0149392" quat="0.413961 0.347354 0.540852 -0.644562" type="mesh" mesh="RFinger22_0.10"/>
              <geom pos="0.0708567 -0.0159358 -0.0277995" quat="0.0543039 0.0455657 0.64117 -0.764117" type="mesh" mesh="RFinger23_0.10"/>
              <geom pos="0.06907 0.01157 -0.00304" quat="0.564115 0.672285 0.367228 -0.30814" type="mesh" mesh="RFinger11_0.10"/>
              <geom pos="0.07683 0.0136681 -0.0149392" quat="0.347355 0.41396 0.644562 -0.540852" type="mesh" mesh="RFinger12_0.10"/>
              <geom pos="0.0708567 0.0159358 -0.0277995" quat="0.0455666 0.0543032 0.764117 -0.641171" type="mesh" mesh="RFinger13_0.10"/>
              <geom pos="0.04895 0 -0.02638" quat="0.706908 -0.70691 0.0167209 0.016721" type="mesh" mesh="RThumb1_0.10"/>
              <geom pos="0.0632939 -4.68797e-10 -0.027059" quat="0.628403 -0.628405 -0.324205 -0.324204" type="mesh" mesh="RThumb2_0.10"/>
              <body name="r_gripper" pos="0.05775 0 -0.01213">
                <inertial pos="0 0 0" mass="2e-06" diaginertia="1.1e-09 1.1e-09 1.1e-09"/>
                <joint name="RHand" pos="0 0 0" axis="1 0 0" range="0 1" actuatorfrcrange="-0.292 0.292"/>
              </body>
            </body>
          </body>
        </body>
      </body>
    </body>
  </worldbody>
  
  <!-- setup scene -->
  <statistic center="1.0 0.7 1.0" extent="0.8"/>
  <visual>
    <headlight diffuse="0.6 0.6 0.6" ambient="0.1 0.1 0.1" specular="0.9 0.9 0.9"/>
    <rgba haze="0.15 0.25 0.35 1"/>
    <global azimuth="-140" elevation="-20" offwidth="2080" offheight="1170"/>
  </visual>
  <asset>
     <texture type="skybox" builtin="gradient" rgb1="1 1 1" rgb2="1 1 1" width="800" height="800"/>
    <texture type="2d" name="groundplane" builtin="checker" mark="edge" rgb1="1 1 1" rgb2="1 1 1" markrgb="0 0 0"
      width="300" height="300"/>
    <material name="groundplane" texture="groundplane" texuniform="true" texrepeat="5 5" reflectance="0"/>
    <texture type="skybox" builtin="gradient" rgb1=".4 .5 .6" rgb2="0 0 0" width="100" height="100"/>
    <texture builtin="flat" height="1278" mark="cross" markrgb="1 1 1" name="texgeom" random="0.01" rgb1="0.8 0.6 0.4" rgb2="0.8 0.6 0.4" type="cube" width="127"/>
    <texture name="texplane" builtin="checker" height="512" width="512" rgb1=".2 .3 .4" rgb2=".1 .15 .2" type="2d" />
    <material name="MatPlane" reflectance="0.5" shininess="0.01" specular="0.1" texrepeat="1 1" texture="texplane" texuniform="true" />
    <material name="geom" texture="texgeom" texuniform="true"/>
  </asset>
   <worldbody>
    <geom name="floor" size="0 0 0.01" type="plane" material="groundplane" contype="1" conaffinity="0" priority="1"
      friction="0.6" condim="3"/>

        <light diffuse=".5 .5 .5" pos="-3 -3 5" dir="3 3 -5" castshadow="true"/>

  </worldbody>
</mujoco>
